{
 "cells": [
  {
   "cell_type": "code",
   "execution_count": 1,
   "metadata": {},
   "outputs": [],
   "source": [
    "from model_utils import *"
   ]
  },
  {
   "cell_type": "code",
   "execution_count": 2,
   "metadata": {},
   "outputs": [],
   "source": [
    "df_train, df_test = get_raw_data()"
   ]
  },
  {
   "cell_type": "code",
   "execution_count": 3,
   "metadata": {},
   "outputs": [
    {
     "name": "stdout",
     "output_type": "stream",
     "text": [
      "pycaret version:  2.3.10\n"
     ]
    }
   ],
   "source": [
    "# check pycaret version\n",
    "print('pycaret version: ', pycaret.__version__) "
   ]
  },
  {
   "cell_type": "code",
   "execution_count": 4,
   "metadata": {},
   "outputs": [
    {
     "data": {
      "text/plain": [
       "0    932\n",
       "1    171\n",
       "Name: target, dtype: int64"
      ]
     },
     "execution_count": 4,
     "metadata": {},
     "output_type": "execute_result"
    }
   ],
   "source": [
    "df_test.target.value_counts()"
   ]
  },
  {
   "cell_type": "code",
   "execution_count": 9,
   "metadata": {},
   "outputs": [
    {
     "name": "stdout",
     "output_type": "stream",
     "text": [
      "REPOSITORY               TAG       IMAGE ID       CREATED        SIZE\n",
      "fraud_voting_model_api   latest    a36def49a37e   8 days ago     2.19GB\n",
      "docker/getting-started   latest    3e4394f6b72f   3 months ago   47MB\n"
     ]
    }
   ],
   "source": [
    "!docker images"
   ]
  },
  {
   "cell_type": "code",
   "execution_count": 10,
   "metadata": {},
   "outputs": [
    {
     "name": "stdout",
     "output_type": "stream",
     "text": [
      "fraud_voting_model_api\n"
     ]
    }
   ],
   "source": [
    "!docker start fraud_voting_model_api"
   ]
  },
  {
   "cell_type": "code",
   "execution_count": 11,
   "metadata": {},
   "outputs": [
    {
     "name": "stdout",
     "output_type": "stream",
     "text": [
      "CONTAINER ID   IMAGE                           COMMAND                  CREATED      STATUS         PORTS                    NAMES\n",
      "1140b98eb6e9   fraud_voting_model_api:latest   \"python fraud_votingâ€¦\"   8 days ago   Up 6 seconds   0.0.0.0:8000->8000/tcp   fraud_voting_model_api\n"
     ]
    }
   ],
   "source": [
    "# check the container is running\n",
    "!docker ps"
   ]
  },
  {
   "cell_type": "code",
   "execution_count": 12,
   "metadata": {},
   "outputs": [
    {
     "data": {
      "text/plain": [
       "{'Time': 93823.0,\n",
       " 'V1': -3.8219388009,\n",
       " 'V2': 5.6672473091,\n",
       " 'V3': -9.2449634577,\n",
       " 'V4': 8.246146934,\n",
       " 'V5': -4.3682860866,\n",
       " 'V6': -3.4507345182,\n",
       " 'V7': -8.4273780293,\n",
       " 'V8': 2.3056085048,\n",
       " 'V9': -5.3380791839,\n",
       " 'V10': -12.0111608836,\n",
       " 'V11': 8.6212550814,\n",
       " 'V12': -18.6837146333,\n",
       " 'V13': -0.9620734284,\n",
       " 'V14': -15.2976561861,\n",
       " 'V15': -2.4141321234,\n",
       " 'V16': -12.1056022452,\n",
       " 'V17': -21.3381950868,\n",
       " 'V18': -8.0454357156,\n",
       " 'V19': 0.1560150328,\n",
       " 'V20': 1.1152468889,\n",
       " 'V21': 1.9905197051,\n",
       " 'V22': 0.0833533216,\n",
       " 'V23': -0.062263553,\n",
       " 'V24': 0.3901878021,\n",
       " 'V25': 0.3298838845,\n",
       " 'V26': 0.0980170826,\n",
       " 'V27': 1.869570163,\n",
       " 'V28': 1.0008495629,\n",
       " 'Amount': 75.86,\n",
       " 'target': 1.0}"
      ]
     },
     "execution_count": 12,
     "metadata": {},
     "output_type": "execute_result"
    }
   ],
   "source": [
    "import json\n",
    "import requests\n",
    "params = json.loads(df_test.loc[df_test.target == 1].iloc[0].to_json())\n",
    "params"
   ]
  },
  {
   "cell_type": "code",
   "execution_count": 13,
   "metadata": {},
   "outputs": [
    {
     "name": "stdout",
     "output_type": "stream",
     "text": [
      "CONTAINER ID   IMAGE     COMMAND   CREATED   STATUS    PORTS     NAMES\n"
     ]
    }
   ],
   "source": [
    "# check docker running container \n",
    "!docker ps"
   ]
  },
  {
   "cell_type": "code",
   "execution_count": 14,
   "metadata": {},
   "outputs": [
    {
     "name": "stderr",
     "output_type": "stream",
     "text": [
      "Traceback (most recent call last):\n",
      "  File \"fraud_voting_model_api.py\", line 11, in <module>\n",
      "    model = load_model('fraud_voting_model_api')\n",
      "  File \"/usr/local/lib/python3.8/site-packages/pycaret/classification/functional.py\", line 2474, in load_model\n",
      "    return experiment.load_model(\n",
      "  File \"/usr/local/lib/python3.8/site-packages/pycaret/classification/oop.py\", line 3113, in load_model\n",
      "    return super().load_model(\n",
      "  File \"/usr/local/lib/python3.8/site-packages/pycaret/internal/pycaret_experiment/tabular_experiment.py\", line 2473, in load_model\n",
      "    return pycaret.internal.persistence.load_model(\n",
      "  File \"/usr/local/lib/python3.8/site-packages/pycaret/internal/persistence.py\", line 391, in load_model\n",
      "    model = joblib.load(model_name)\n",
      "  File \"/usr/local/lib/python3.8/site-packages/joblib/numpy_pickle.py\", line 658, in load\n",
      "    obj = _unpickle(fobj, filename, mmap_mode)\n",
      "  File \"/usr/local/lib/python3.8/site-packages/joblib/numpy_pickle.py\", line 577, in _unpickle\n",
      "    obj = unpickler.load()\n",
      "  File \"/usr/local/lib/python3.8/pickle.py\", line 1212, in load\n",
      "    dispatch[key[0]](self)\n",
      "  File \"/usr/local/lib/python3.8/pickle.py\", line 1537, in load_stack_global\n",
      "    self.append(self.find_class(module, name))\n",
      "  File \"/usr/local/lib/python3.8/pickle.py\", line 1581, in find_class\n",
      "    return _getattribute(sys.modules[module], name)[0]\n",
      "  File \"/usr/local/lib/python3.8/pickle.py\", line 331, in _getattribute\n",
      "    raise AttributeError(\"Can't get attribute {!r} on {!r}\"\n",
      "AttributeError: Can't get attribute 'DataTypes_Auto_infer' on <module 'pycaret.internal.preprocess' from '/usr/local/lib/python3.8/site-packages/pycaret/internal/preprocess/__init__.py'>\n",
      "Traceback (most recent call last):\n",
      "  File \"fraud_voting_model_api.py\", line 11, in <module>\n",
      "    model = load_model('fraud_voting_model_api')\n",
      "  File \"/usr/local/lib/python3.8/site-packages/pycaret/classification/functional.py\", line 2474, in load_model\n",
      "    return experiment.load_model(\n",
      "  File \"/usr/local/lib/python3.8/site-packages/pycaret/classification/oop.py\", line 3113, in load_model\n",
      "    return super().load_model(\n",
      "  File \"/usr/local/lib/python3.8/site-packages/pycaret/internal/pycaret_experiment/tabular_experiment.py\", line 2473, in load_model\n",
      "    return pycaret.internal.persistence.load_model(\n",
      "  File \"/usr/local/lib/python3.8/site-packages/pycaret/internal/persistence.py\", line 391, in load_model\n",
      "    model = joblib.load(model_name)\n",
      "  File \"/usr/local/lib/python3.8/site-packages/joblib/numpy_pickle.py\", line 658, in load\n",
      "    obj = _unpickle(fobj, filename, mmap_mode)\n",
      "  File \"/usr/local/lib/python3.8/site-packages/joblib/numpy_pickle.py\", line 577, in _unpickle\n",
      "    obj = unpickler.load()\n",
      "  File \"/usr/local/lib/python3.8/pickle.py\", line 1212, in load\n",
      "    dispatch[key[0]](self)\n",
      "  File \"/usr/local/lib/python3.8/pickle.py\", line 1537, in load_stack_global\n",
      "    self.append(self.find_class(module, name))\n",
      "  File \"/usr/local/lib/python3.8/pickle.py\", line 1581, in find_class\n",
      "    return _getattribute(sys.modules[module], name)[0]\n",
      "  File \"/usr/local/lib/python3.8/pickle.py\", line 331, in _getattribute\n",
      "    raise AttributeError(\"Can't get attribute {!r} on {!r}\"\n",
      "AttributeError: Can't get attribute 'DataTypes_Auto_infer' on <module 'pycaret.internal.preprocess' from '/usr/local/lib/python3.8/site-packages/pycaret/internal/preprocess/__init__.py'>\n",
      "Traceback (most recent call last):\n",
      "  File \"fraud_voting_model_api.py\", line 11, in <module>\n",
      "    model = load_model('fraud_voting_model_api')\n",
      "  File \"/usr/local/lib/python3.8/site-packages/pycaret/classification/functional.py\", line 2474, in load_model\n",
      "    return experiment.load_model(\n",
      "  File \"/usr/local/lib/python3.8/site-packages/pycaret/classification/oop.py\", line 3113, in load_model\n",
      "    return super().load_model(\n",
      "  File \"/usr/local/lib/python3.8/site-packages/pycaret/internal/pycaret_experiment/tabular_experiment.py\", line 2473, in load_model\n",
      "    return pycaret.internal.persistence.load_model(\n",
      "  File \"/usr/local/lib/python3.8/site-packages/pycaret/internal/persistence.py\", line 391, in load_model\n",
      "    model = joblib.load(model_name)\n",
      "  File \"/usr/local/lib/python3.8/site-packages/joblib/numpy_pickle.py\", line 658, in load\n",
      "    obj = _unpickle(fobj, filename, mmap_mode)\n",
      "  File \"/usr/local/lib/python3.8/site-packages/joblib/numpy_pickle.py\", line 577, in _unpickle\n",
      "    obj = unpickler.load()\n",
      "  File \"/usr/local/lib/python3.8/pickle.py\", line 1212, in load\n",
      "    dispatch[key[0]](self)\n",
      "  File \"/usr/local/lib/python3.8/pickle.py\", line 1537, in load_stack_global\n",
      "    self.append(self.find_class(module, name))\n",
      "  File \"/usr/local/lib/python3.8/pickle.py\", line 1581, in find_class\n",
      "    return _getattribute(sys.modules[module], name)[0]\n",
      "  File \"/usr/local/lib/python3.8/pickle.py\", line 331, in _getattribute\n",
      "    raise AttributeError(\"Can't get attribute {!r} on {!r}\"\n",
      "AttributeError: Can't get attribute 'DataTypes_Auto_infer' on <module 'pycaret.internal.preprocess' from '/usr/local/lib/python3.8/site-packages/pycaret/internal/preprocess/__init__.py'>\n",
      "Traceback (most recent call last):\n",
      "  File \"fraud_voting_model_api.py\", line 11, in <module>\n",
      "    model = load_model('fraud_voting_model_api')\n",
      "  File \"/usr/local/lib/python3.8/site-packages/pycaret/classification/functional.py\", line 2474, in load_model\n",
      "    return experiment.load_model(\n",
      "  File \"/usr/local/lib/python3.8/site-packages/pycaret/classification/oop.py\", line 3113, in load_model\n",
      "    return super().load_model(\n",
      "  File \"/usr/local/lib/python3.8/site-packages/pycaret/internal/pycaret_experiment/tabular_experiment.py\", line 2473, in load_model\n",
      "    return pycaret.internal.persistence.load_model(\n",
      "  File \"/usr/local/lib/python3.8/site-packages/pycaret/internal/persistence.py\", line 391, in load_model\n",
      "    model = joblib.load(model_name)\n",
      "  File \"/usr/local/lib/python3.8/site-packages/joblib/numpy_pickle.py\", line 658, in load\n",
      "    obj = _unpickle(fobj, filename, mmap_mode)\n",
      "  File \"/usr/local/lib/python3.8/site-packages/joblib/numpy_pickle.py\", line 577, in _unpickle\n",
      "    obj = unpickler.load()\n",
      "  File \"/usr/local/lib/python3.8/pickle.py\", line 1212, in load\n",
      "    dispatch[key[0]](self)\n",
      "  File \"/usr/local/lib/python3.8/pickle.py\", line 1537, in load_stack_global\n",
      "    self.append(self.find_class(module, name))\n",
      "  File \"/usr/local/lib/python3.8/pickle.py\", line 1581, in find_class\n",
      "    return _getattribute(sys.modules[module], name)[0]\n",
      "  File \"/usr/local/lib/python3.8/pickle.py\", line 331, in _getattribute\n",
      "    raise AttributeError(\"Can't get attribute {!r} on {!r}\"\n",
      "AttributeError: Can't get attribute 'DataTypes_Auto_infer' on <module 'pycaret.internal.preprocess' from '/usr/local/lib/python3.8/site-packages/pycaret/internal/preprocess/__init__.py'>\n"
     ]
    }
   ],
   "source": [
    "!docker logs fraud_voting_model_api"
   ]
  },
  {
   "cell_type": "code",
   "execution_count": 25,
   "metadata": {},
   "outputs": [
    {
     "name": "stdout",
     "output_type": "stream",
     "text": [
      "^C\n"
     ]
    }
   ],
   "source": [
    "# run the FAST API\n",
    "# !python fraud_voting_model_api.py"
   ]
  },
  {
   "cell_type": "code",
   "execution_count": 16,
   "metadata": {},
   "outputs": [
    {
     "ename": "ConnectionError",
     "evalue": "('Connection aborted.', RemoteDisconnected('Remote end closed connection without response'))",
     "output_type": "error",
     "traceback": [
      "\u001b[1;31m---------------------------------------------------------------------------\u001b[0m",
      "\u001b[1;31mRemoteDisconnected\u001b[0m                        Traceback (most recent call last)",
      "File \u001b[1;32m~\\AppData\\Roaming\\Python\\Python38\\site-packages\\urllib3\\connectionpool.py:703\u001b[0m, in \u001b[0;36mHTTPConnectionPool.urlopen\u001b[1;34m(self, method, url, body, headers, retries, redirect, assert_same_host, timeout, pool_timeout, release_conn, chunked, body_pos, **response_kw)\u001b[0m\n\u001b[0;32m    702\u001b[0m \u001b[39m# Make the request on the httplib connection object.\u001b[39;00m\n\u001b[1;32m--> 703\u001b[0m httplib_response \u001b[39m=\u001b[39m \u001b[39mself\u001b[39;49m\u001b[39m.\u001b[39;49m_make_request(\n\u001b[0;32m    704\u001b[0m     conn,\n\u001b[0;32m    705\u001b[0m     method,\n\u001b[0;32m    706\u001b[0m     url,\n\u001b[0;32m    707\u001b[0m     timeout\u001b[39m=\u001b[39;49mtimeout_obj,\n\u001b[0;32m    708\u001b[0m     body\u001b[39m=\u001b[39;49mbody,\n\u001b[0;32m    709\u001b[0m     headers\u001b[39m=\u001b[39;49mheaders,\n\u001b[0;32m    710\u001b[0m     chunked\u001b[39m=\u001b[39;49mchunked,\n\u001b[0;32m    711\u001b[0m )\n\u001b[0;32m    713\u001b[0m \u001b[39m# If we're going to release the connection in ``finally:``, then\u001b[39;00m\n\u001b[0;32m    714\u001b[0m \u001b[39m# the response doesn't need to know about the connection. Otherwise\u001b[39;00m\n\u001b[0;32m    715\u001b[0m \u001b[39m# it will also try to release it and we'll have a double-release\u001b[39;00m\n\u001b[0;32m    716\u001b[0m \u001b[39m# mess.\u001b[39;00m\n",
      "File \u001b[1;32m~\\AppData\\Roaming\\Python\\Python38\\site-packages\\urllib3\\connectionpool.py:449\u001b[0m, in \u001b[0;36mHTTPConnectionPool._make_request\u001b[1;34m(self, conn, method, url, timeout, chunked, **httplib_request_kw)\u001b[0m\n\u001b[0;32m    445\u001b[0m         \u001b[39mexcept\u001b[39;00m \u001b[39mBaseException\u001b[39;00m \u001b[39mas\u001b[39;00m e:\n\u001b[0;32m    446\u001b[0m             \u001b[39m# Remove the TypeError from the exception chain in\u001b[39;00m\n\u001b[0;32m    447\u001b[0m             \u001b[39m# Python 3 (including for exceptions like SystemExit).\u001b[39;00m\n\u001b[0;32m    448\u001b[0m             \u001b[39m# Otherwise it looks like a bug in the code.\u001b[39;00m\n\u001b[1;32m--> 449\u001b[0m             six\u001b[39m.\u001b[39;49mraise_from(e, \u001b[39mNone\u001b[39;49;00m)\n\u001b[0;32m    450\u001b[0m \u001b[39mexcept\u001b[39;00m (SocketTimeout, BaseSSLError, SocketError) \u001b[39mas\u001b[39;00m e:\n",
      "File \u001b[1;32m<string>:3\u001b[0m, in \u001b[0;36mraise_from\u001b[1;34m(value, from_value)\u001b[0m\n",
      "File \u001b[1;32m~\\AppData\\Roaming\\Python\\Python38\\site-packages\\urllib3\\connectionpool.py:444\u001b[0m, in \u001b[0;36mHTTPConnectionPool._make_request\u001b[1;34m(self, conn, method, url, timeout, chunked, **httplib_request_kw)\u001b[0m\n\u001b[0;32m    443\u001b[0m \u001b[39mtry\u001b[39;00m:\n\u001b[1;32m--> 444\u001b[0m     httplib_response \u001b[39m=\u001b[39m conn\u001b[39m.\u001b[39;49mgetresponse()\n\u001b[0;32m    445\u001b[0m \u001b[39mexcept\u001b[39;00m \u001b[39mBaseException\u001b[39;00m \u001b[39mas\u001b[39;00m e:\n\u001b[0;32m    446\u001b[0m     \u001b[39m# Remove the TypeError from the exception chain in\u001b[39;00m\n\u001b[0;32m    447\u001b[0m     \u001b[39m# Python 3 (including for exceptions like SystemExit).\u001b[39;00m\n\u001b[0;32m    448\u001b[0m     \u001b[39m# Otherwise it looks like a bug in the code.\u001b[39;00m\n",
      "File \u001b[1;32mc:\\Users\\Abdur Raffay Khan\\AppData\\Local\\Programs\\Python\\Python38\\lib\\http\\client.py:1347\u001b[0m, in \u001b[0;36mHTTPConnection.getresponse\u001b[1;34m(self)\u001b[0m\n\u001b[0;32m   1346\u001b[0m \u001b[39mtry\u001b[39;00m:\n\u001b[1;32m-> 1347\u001b[0m     response\u001b[39m.\u001b[39;49mbegin()\n\u001b[0;32m   1348\u001b[0m \u001b[39mexcept\u001b[39;00m \u001b[39mConnectionError\u001b[39;00m:\n",
      "File \u001b[1;32mc:\\Users\\Abdur Raffay Khan\\AppData\\Local\\Programs\\Python\\Python38\\lib\\http\\client.py:307\u001b[0m, in \u001b[0;36mHTTPResponse.begin\u001b[1;34m(self)\u001b[0m\n\u001b[0;32m    306\u001b[0m \u001b[39mwhile\u001b[39;00m \u001b[39mTrue\u001b[39;00m:\n\u001b[1;32m--> 307\u001b[0m     version, status, reason \u001b[39m=\u001b[39m \u001b[39mself\u001b[39;49m\u001b[39m.\u001b[39;49m_read_status()\n\u001b[0;32m    308\u001b[0m     \u001b[39mif\u001b[39;00m status \u001b[39m!=\u001b[39m CONTINUE:\n",
      "File \u001b[1;32mc:\\Users\\Abdur Raffay Khan\\AppData\\Local\\Programs\\Python\\Python38\\lib\\http\\client.py:276\u001b[0m, in \u001b[0;36mHTTPResponse._read_status\u001b[1;34m(self)\u001b[0m\n\u001b[0;32m    273\u001b[0m \u001b[39mif\u001b[39;00m \u001b[39mnot\u001b[39;00m line:\n\u001b[0;32m    274\u001b[0m     \u001b[39m# Presumably, the server closed the connection before\u001b[39;00m\n\u001b[0;32m    275\u001b[0m     \u001b[39m# sending a valid response.\u001b[39;00m\n\u001b[1;32m--> 276\u001b[0m     \u001b[39mraise\u001b[39;00m RemoteDisconnected(\u001b[39m\"\u001b[39m\u001b[39mRemote end closed connection without\u001b[39m\u001b[39m\"\u001b[39m\n\u001b[0;32m    277\u001b[0m                              \u001b[39m\"\u001b[39m\u001b[39m response\u001b[39m\u001b[39m\"\u001b[39m)\n\u001b[0;32m    278\u001b[0m \u001b[39mtry\u001b[39;00m:\n",
      "\u001b[1;31mRemoteDisconnected\u001b[0m: Remote end closed connection without response",
      "\nDuring handling of the above exception, another exception occurred:\n",
      "\u001b[1;31mProtocolError\u001b[0m                             Traceback (most recent call last)",
      "File \u001b[1;32m~\\AppData\\Roaming\\Python\\Python38\\site-packages\\requests\\adapters.py:489\u001b[0m, in \u001b[0;36mHTTPAdapter.send\u001b[1;34m(self, request, stream, timeout, verify, cert, proxies)\u001b[0m\n\u001b[0;32m    488\u001b[0m \u001b[39mif\u001b[39;00m \u001b[39mnot\u001b[39;00m chunked:\n\u001b[1;32m--> 489\u001b[0m     resp \u001b[39m=\u001b[39m conn\u001b[39m.\u001b[39;49murlopen(\n\u001b[0;32m    490\u001b[0m         method\u001b[39m=\u001b[39;49mrequest\u001b[39m.\u001b[39;49mmethod,\n\u001b[0;32m    491\u001b[0m         url\u001b[39m=\u001b[39;49murl,\n\u001b[0;32m    492\u001b[0m         body\u001b[39m=\u001b[39;49mrequest\u001b[39m.\u001b[39;49mbody,\n\u001b[0;32m    493\u001b[0m         headers\u001b[39m=\u001b[39;49mrequest\u001b[39m.\u001b[39;49mheaders,\n\u001b[0;32m    494\u001b[0m         redirect\u001b[39m=\u001b[39;49m\u001b[39mFalse\u001b[39;49;00m,\n\u001b[0;32m    495\u001b[0m         assert_same_host\u001b[39m=\u001b[39;49m\u001b[39mFalse\u001b[39;49;00m,\n\u001b[0;32m    496\u001b[0m         preload_content\u001b[39m=\u001b[39;49m\u001b[39mFalse\u001b[39;49;00m,\n\u001b[0;32m    497\u001b[0m         decode_content\u001b[39m=\u001b[39;49m\u001b[39mFalse\u001b[39;49;00m,\n\u001b[0;32m    498\u001b[0m         retries\u001b[39m=\u001b[39;49m\u001b[39mself\u001b[39;49m\u001b[39m.\u001b[39;49mmax_retries,\n\u001b[0;32m    499\u001b[0m         timeout\u001b[39m=\u001b[39;49mtimeout,\n\u001b[0;32m    500\u001b[0m     )\n\u001b[0;32m    502\u001b[0m \u001b[39m# Send the request.\u001b[39;00m\n\u001b[0;32m    503\u001b[0m \u001b[39melse\u001b[39;00m:\n",
      "File \u001b[1;32m~\\AppData\\Roaming\\Python\\Python38\\site-packages\\urllib3\\connectionpool.py:787\u001b[0m, in \u001b[0;36mHTTPConnectionPool.urlopen\u001b[1;34m(self, method, url, body, headers, retries, redirect, assert_same_host, timeout, pool_timeout, release_conn, chunked, body_pos, **response_kw)\u001b[0m\n\u001b[0;32m    785\u001b[0m     e \u001b[39m=\u001b[39m ProtocolError(\u001b[39m\"\u001b[39m\u001b[39mConnection aborted.\u001b[39m\u001b[39m\"\u001b[39m, e)\n\u001b[1;32m--> 787\u001b[0m retries \u001b[39m=\u001b[39m retries\u001b[39m.\u001b[39;49mincrement(\n\u001b[0;32m    788\u001b[0m     method, url, error\u001b[39m=\u001b[39;49me, _pool\u001b[39m=\u001b[39;49m\u001b[39mself\u001b[39;49m, _stacktrace\u001b[39m=\u001b[39;49msys\u001b[39m.\u001b[39;49mexc_info()[\u001b[39m2\u001b[39;49m]\n\u001b[0;32m    789\u001b[0m )\n\u001b[0;32m    790\u001b[0m retries\u001b[39m.\u001b[39msleep()\n",
      "File \u001b[1;32m~\\AppData\\Roaming\\Python\\Python38\\site-packages\\urllib3\\util\\retry.py:550\u001b[0m, in \u001b[0;36mRetry.increment\u001b[1;34m(self, method, url, response, error, _pool, _stacktrace)\u001b[0m\n\u001b[0;32m    549\u001b[0m \u001b[39mif\u001b[39;00m read \u001b[39mis\u001b[39;00m \u001b[39mFalse\u001b[39;00m \u001b[39mor\u001b[39;00m \u001b[39mnot\u001b[39;00m \u001b[39mself\u001b[39m\u001b[39m.\u001b[39m_is_method_retryable(method):\n\u001b[1;32m--> 550\u001b[0m     \u001b[39mraise\u001b[39;00m six\u001b[39m.\u001b[39;49mreraise(\u001b[39mtype\u001b[39;49m(error), error, _stacktrace)\n\u001b[0;32m    551\u001b[0m \u001b[39melif\u001b[39;00m read \u001b[39mis\u001b[39;00m \u001b[39mnot\u001b[39;00m \u001b[39mNone\u001b[39;00m:\n",
      "File \u001b[1;32m~\\AppData\\Roaming\\Python\\Python38\\site-packages\\urllib3\\packages\\six.py:769\u001b[0m, in \u001b[0;36mreraise\u001b[1;34m(tp, value, tb)\u001b[0m\n\u001b[0;32m    768\u001b[0m \u001b[39mif\u001b[39;00m value\u001b[39m.\u001b[39m__traceback__ \u001b[39mis\u001b[39;00m \u001b[39mnot\u001b[39;00m tb:\n\u001b[1;32m--> 769\u001b[0m     \u001b[39mraise\u001b[39;00m value\u001b[39m.\u001b[39mwith_traceback(tb)\n\u001b[0;32m    770\u001b[0m \u001b[39mraise\u001b[39;00m value\n",
      "File \u001b[1;32m~\\AppData\\Roaming\\Python\\Python38\\site-packages\\urllib3\\connectionpool.py:703\u001b[0m, in \u001b[0;36mHTTPConnectionPool.urlopen\u001b[1;34m(self, method, url, body, headers, retries, redirect, assert_same_host, timeout, pool_timeout, release_conn, chunked, body_pos, **response_kw)\u001b[0m\n\u001b[0;32m    702\u001b[0m \u001b[39m# Make the request on the httplib connection object.\u001b[39;00m\n\u001b[1;32m--> 703\u001b[0m httplib_response \u001b[39m=\u001b[39m \u001b[39mself\u001b[39;49m\u001b[39m.\u001b[39;49m_make_request(\n\u001b[0;32m    704\u001b[0m     conn,\n\u001b[0;32m    705\u001b[0m     method,\n\u001b[0;32m    706\u001b[0m     url,\n\u001b[0;32m    707\u001b[0m     timeout\u001b[39m=\u001b[39;49mtimeout_obj,\n\u001b[0;32m    708\u001b[0m     body\u001b[39m=\u001b[39;49mbody,\n\u001b[0;32m    709\u001b[0m     headers\u001b[39m=\u001b[39;49mheaders,\n\u001b[0;32m    710\u001b[0m     chunked\u001b[39m=\u001b[39;49mchunked,\n\u001b[0;32m    711\u001b[0m )\n\u001b[0;32m    713\u001b[0m \u001b[39m# If we're going to release the connection in ``finally:``, then\u001b[39;00m\n\u001b[0;32m    714\u001b[0m \u001b[39m# the response doesn't need to know about the connection. Otherwise\u001b[39;00m\n\u001b[0;32m    715\u001b[0m \u001b[39m# it will also try to release it and we'll have a double-release\u001b[39;00m\n\u001b[0;32m    716\u001b[0m \u001b[39m# mess.\u001b[39;00m\n",
      "File \u001b[1;32m~\\AppData\\Roaming\\Python\\Python38\\site-packages\\urllib3\\connectionpool.py:449\u001b[0m, in \u001b[0;36mHTTPConnectionPool._make_request\u001b[1;34m(self, conn, method, url, timeout, chunked, **httplib_request_kw)\u001b[0m\n\u001b[0;32m    445\u001b[0m         \u001b[39mexcept\u001b[39;00m \u001b[39mBaseException\u001b[39;00m \u001b[39mas\u001b[39;00m e:\n\u001b[0;32m    446\u001b[0m             \u001b[39m# Remove the TypeError from the exception chain in\u001b[39;00m\n\u001b[0;32m    447\u001b[0m             \u001b[39m# Python 3 (including for exceptions like SystemExit).\u001b[39;00m\n\u001b[0;32m    448\u001b[0m             \u001b[39m# Otherwise it looks like a bug in the code.\u001b[39;00m\n\u001b[1;32m--> 449\u001b[0m             six\u001b[39m.\u001b[39;49mraise_from(e, \u001b[39mNone\u001b[39;49;00m)\n\u001b[0;32m    450\u001b[0m \u001b[39mexcept\u001b[39;00m (SocketTimeout, BaseSSLError, SocketError) \u001b[39mas\u001b[39;00m e:\n",
      "File \u001b[1;32m<string>:3\u001b[0m, in \u001b[0;36mraise_from\u001b[1;34m(value, from_value)\u001b[0m\n",
      "File \u001b[1;32m~\\AppData\\Roaming\\Python\\Python38\\site-packages\\urllib3\\connectionpool.py:444\u001b[0m, in \u001b[0;36mHTTPConnectionPool._make_request\u001b[1;34m(self, conn, method, url, timeout, chunked, **httplib_request_kw)\u001b[0m\n\u001b[0;32m    443\u001b[0m \u001b[39mtry\u001b[39;00m:\n\u001b[1;32m--> 444\u001b[0m     httplib_response \u001b[39m=\u001b[39m conn\u001b[39m.\u001b[39;49mgetresponse()\n\u001b[0;32m    445\u001b[0m \u001b[39mexcept\u001b[39;00m \u001b[39mBaseException\u001b[39;00m \u001b[39mas\u001b[39;00m e:\n\u001b[0;32m    446\u001b[0m     \u001b[39m# Remove the TypeError from the exception chain in\u001b[39;00m\n\u001b[0;32m    447\u001b[0m     \u001b[39m# Python 3 (including for exceptions like SystemExit).\u001b[39;00m\n\u001b[0;32m    448\u001b[0m     \u001b[39m# Otherwise it looks like a bug in the code.\u001b[39;00m\n",
      "File \u001b[1;32mc:\\Users\\Abdur Raffay Khan\\AppData\\Local\\Programs\\Python\\Python38\\lib\\http\\client.py:1347\u001b[0m, in \u001b[0;36mHTTPConnection.getresponse\u001b[1;34m(self)\u001b[0m\n\u001b[0;32m   1346\u001b[0m \u001b[39mtry\u001b[39;00m:\n\u001b[1;32m-> 1347\u001b[0m     response\u001b[39m.\u001b[39;49mbegin()\n\u001b[0;32m   1348\u001b[0m \u001b[39mexcept\u001b[39;00m \u001b[39mConnectionError\u001b[39;00m:\n",
      "File \u001b[1;32mc:\\Users\\Abdur Raffay Khan\\AppData\\Local\\Programs\\Python\\Python38\\lib\\http\\client.py:307\u001b[0m, in \u001b[0;36mHTTPResponse.begin\u001b[1;34m(self)\u001b[0m\n\u001b[0;32m    306\u001b[0m \u001b[39mwhile\u001b[39;00m \u001b[39mTrue\u001b[39;00m:\n\u001b[1;32m--> 307\u001b[0m     version, status, reason \u001b[39m=\u001b[39m \u001b[39mself\u001b[39;49m\u001b[39m.\u001b[39;49m_read_status()\n\u001b[0;32m    308\u001b[0m     \u001b[39mif\u001b[39;00m status \u001b[39m!=\u001b[39m CONTINUE:\n",
      "File \u001b[1;32mc:\\Users\\Abdur Raffay Khan\\AppData\\Local\\Programs\\Python\\Python38\\lib\\http\\client.py:276\u001b[0m, in \u001b[0;36mHTTPResponse._read_status\u001b[1;34m(self)\u001b[0m\n\u001b[0;32m    273\u001b[0m \u001b[39mif\u001b[39;00m \u001b[39mnot\u001b[39;00m line:\n\u001b[0;32m    274\u001b[0m     \u001b[39m# Presumably, the server closed the connection before\u001b[39;00m\n\u001b[0;32m    275\u001b[0m     \u001b[39m# sending a valid response.\u001b[39;00m\n\u001b[1;32m--> 276\u001b[0m     \u001b[39mraise\u001b[39;00m RemoteDisconnected(\u001b[39m\"\u001b[39m\u001b[39mRemote end closed connection without\u001b[39m\u001b[39m\"\u001b[39m\n\u001b[0;32m    277\u001b[0m                              \u001b[39m\"\u001b[39m\u001b[39m response\u001b[39m\u001b[39m\"\u001b[39m)\n\u001b[0;32m    278\u001b[0m \u001b[39mtry\u001b[39;00m:\n",
      "\u001b[1;31mProtocolError\u001b[0m: ('Connection aborted.', RemoteDisconnected('Remote end closed connection without response'))",
      "\nDuring handling of the above exception, another exception occurred:\n",
      "\u001b[1;31mConnectionError\u001b[0m                           Traceback (most recent call last)",
      "Cell \u001b[1;32mIn[16], line 9\u001b[0m\n\u001b[0;32m      4\u001b[0m \u001b[39m# params = json.loads(df_test.loc[df_test.target == 1].iloc[0].to_json())\u001b[39;00m\n\u001b[0;32m      5\u001b[0m \u001b[39m# response = requests.post(url, json=params)\u001b[39;00m\n\u001b[0;32m      6\u001b[0m \u001b[39m# response.json()\u001b[39;00m\n\u001b[0;32m      8\u001b[0m params \u001b[39m=\u001b[39m json\u001b[39m.\u001b[39mloads(df_test\u001b[39m.\u001b[39mloc[df_test\u001b[39m.\u001b[39mtarget \u001b[39m==\u001b[39m \u001b[39m1\u001b[39m]\u001b[39m.\u001b[39miloc[\u001b[39m0\u001b[39m]\u001b[39m.\u001b[39mto_json())\n\u001b[1;32m----> 9\u001b[0m response \u001b[39m=\u001b[39m requests\u001b[39m.\u001b[39;49mget(url, params)\u001b[39m.\u001b[39mjson()\n\u001b[0;32m     10\u001b[0m \u001b[39mprint\u001b[39m(response)\n",
      "File \u001b[1;32m~\\AppData\\Roaming\\Python\\Python38\\site-packages\\requests\\api.py:73\u001b[0m, in \u001b[0;36mget\u001b[1;34m(url, params, **kwargs)\u001b[0m\n\u001b[0;32m     62\u001b[0m \u001b[39mdef\u001b[39;00m \u001b[39mget\u001b[39m(url, params\u001b[39m=\u001b[39m\u001b[39mNone\u001b[39;00m, \u001b[39m*\u001b[39m\u001b[39m*\u001b[39mkwargs):\n\u001b[0;32m     63\u001b[0m \u001b[39m    \u001b[39m\u001b[39mr\u001b[39m\u001b[39m\"\"\"Sends a GET request.\u001b[39;00m\n\u001b[0;32m     64\u001b[0m \n\u001b[0;32m     65\u001b[0m \u001b[39m    :param url: URL for the new :class:`Request` object.\u001b[39;00m\n\u001b[1;32m   (...)\u001b[0m\n\u001b[0;32m     70\u001b[0m \u001b[39m    :rtype: requests.Response\u001b[39;00m\n\u001b[0;32m     71\u001b[0m \u001b[39m    \"\"\"\u001b[39;00m\n\u001b[1;32m---> 73\u001b[0m     \u001b[39mreturn\u001b[39;00m request(\u001b[39m\"\u001b[39;49m\u001b[39mget\u001b[39;49m\u001b[39m\"\u001b[39;49m, url, params\u001b[39m=\u001b[39;49mparams, \u001b[39m*\u001b[39;49m\u001b[39m*\u001b[39;49mkwargs)\n",
      "File \u001b[1;32m~\\AppData\\Roaming\\Python\\Python38\\site-packages\\requests\\api.py:59\u001b[0m, in \u001b[0;36mrequest\u001b[1;34m(method, url, **kwargs)\u001b[0m\n\u001b[0;32m     55\u001b[0m \u001b[39m# By using the 'with' statement we are sure the session is closed, thus we\u001b[39;00m\n\u001b[0;32m     56\u001b[0m \u001b[39m# avoid leaving sockets open which can trigger a ResourceWarning in some\u001b[39;00m\n\u001b[0;32m     57\u001b[0m \u001b[39m# cases, and look like a memory leak in others.\u001b[39;00m\n\u001b[0;32m     58\u001b[0m \u001b[39mwith\u001b[39;00m sessions\u001b[39m.\u001b[39mSession() \u001b[39mas\u001b[39;00m session:\n\u001b[1;32m---> 59\u001b[0m     \u001b[39mreturn\u001b[39;00m session\u001b[39m.\u001b[39;49mrequest(method\u001b[39m=\u001b[39;49mmethod, url\u001b[39m=\u001b[39;49murl, \u001b[39m*\u001b[39;49m\u001b[39m*\u001b[39;49mkwargs)\n",
      "File \u001b[1;32m~\\AppData\\Roaming\\Python\\Python38\\site-packages\\requests\\sessions.py:587\u001b[0m, in \u001b[0;36mSession.request\u001b[1;34m(self, method, url, params, data, headers, cookies, files, auth, timeout, allow_redirects, proxies, hooks, stream, verify, cert, json)\u001b[0m\n\u001b[0;32m    582\u001b[0m send_kwargs \u001b[39m=\u001b[39m {\n\u001b[0;32m    583\u001b[0m     \u001b[39m\"\u001b[39m\u001b[39mtimeout\u001b[39m\u001b[39m\"\u001b[39m: timeout,\n\u001b[0;32m    584\u001b[0m     \u001b[39m\"\u001b[39m\u001b[39mallow_redirects\u001b[39m\u001b[39m\"\u001b[39m: allow_redirects,\n\u001b[0;32m    585\u001b[0m }\n\u001b[0;32m    586\u001b[0m send_kwargs\u001b[39m.\u001b[39mupdate(settings)\n\u001b[1;32m--> 587\u001b[0m resp \u001b[39m=\u001b[39m \u001b[39mself\u001b[39;49m\u001b[39m.\u001b[39;49msend(prep, \u001b[39m*\u001b[39;49m\u001b[39m*\u001b[39;49msend_kwargs)\n\u001b[0;32m    589\u001b[0m \u001b[39mreturn\u001b[39;00m resp\n",
      "File \u001b[1;32m~\\AppData\\Roaming\\Python\\Python38\\site-packages\\requests\\sessions.py:701\u001b[0m, in \u001b[0;36mSession.send\u001b[1;34m(self, request, **kwargs)\u001b[0m\n\u001b[0;32m    698\u001b[0m start \u001b[39m=\u001b[39m preferred_clock()\n\u001b[0;32m    700\u001b[0m \u001b[39m# Send the request\u001b[39;00m\n\u001b[1;32m--> 701\u001b[0m r \u001b[39m=\u001b[39m adapter\u001b[39m.\u001b[39;49msend(request, \u001b[39m*\u001b[39;49m\u001b[39m*\u001b[39;49mkwargs)\n\u001b[0;32m    703\u001b[0m \u001b[39m# Total elapsed time of the request (approximately)\u001b[39;00m\n\u001b[0;32m    704\u001b[0m elapsed \u001b[39m=\u001b[39m preferred_clock() \u001b[39m-\u001b[39m start\n",
      "File \u001b[1;32m~\\AppData\\Roaming\\Python\\Python38\\site-packages\\requests\\adapters.py:547\u001b[0m, in \u001b[0;36mHTTPAdapter.send\u001b[1;34m(self, request, stream, timeout, verify, cert, proxies)\u001b[0m\n\u001b[0;32m    544\u001b[0m             \u001b[39mraise\u001b[39;00m\n\u001b[0;32m    546\u001b[0m \u001b[39mexcept\u001b[39;00m (ProtocolError, \u001b[39mOSError\u001b[39;00m) \u001b[39mas\u001b[39;00m err:\n\u001b[1;32m--> 547\u001b[0m     \u001b[39mraise\u001b[39;00m \u001b[39mConnectionError\u001b[39;00m(err, request\u001b[39m=\u001b[39mrequest)\n\u001b[0;32m    549\u001b[0m \u001b[39mexcept\u001b[39;00m MaxRetryError \u001b[39mas\u001b[39;00m e:\n\u001b[0;32m    550\u001b[0m     \u001b[39mif\u001b[39;00m \u001b[39misinstance\u001b[39m(e\u001b[39m.\u001b[39mreason, ConnectTimeoutError):\n\u001b[0;32m    551\u001b[0m         \u001b[39m# TODO: Remove this in 3.0.0: see #2811\u001b[39;00m\n",
      "\u001b[1;31mConnectionError\u001b[0m: ('Connection aborted.', RemoteDisconnected('Remote end closed connection without response'))"
     ]
    }
   ],
   "source": [
    "import json\n",
    "import requests\n",
    "url = 'http://127.0.0.1:8000/predict'\n",
    "# params = json.loads(df_test.loc[df_test.target == 1].iloc[0].to_json())\n",
    "# response = requests.post(url, json=params)\n",
    "# response.json()\n",
    "\n",
    "params = json.loads(df_test.loc[df_test.target == 1].iloc[0].to_json())\n",
    "response = requests.get(url, params).json()\n",
    "print(response)"
   ]
  },
  {
   "cell_type": "code",
   "execution_count": null,
   "metadata": {},
   "outputs": [],
   "source": []
  }
 ],
 "metadata": {
  "kernelspec": {
   "display_name": "Python 3",
   "language": "python",
   "name": "python3"
  },
  "language_info": {
   "codemirror_mode": {
    "name": "ipython",
    "version": 3
   },
   "file_extension": ".py",
   "mimetype": "text/x-python",
   "name": "python",
   "nbconvert_exporter": "python",
   "pygments_lexer": "ipython3",
   "version": "3.8.6"
  },
  "orig_nbformat": 4,
  "vscode": {
   "interpreter": {
    "hash": "8d86fdd6e6a43d0f65d319308acfa97f1cbbfac2d47559687937a23cc158eaae"
   }
  }
 },
 "nbformat": 4,
 "nbformat_minor": 2
}
